<!--
 Copyright (C) 2013-7 CODYCO Project
 Author: Serena Ivaldi, Joseph Salini
 email:  serena.ivaldi@isir.upmc.fr

 Permission is granted to copy, distribute, and/or modify this program
 under the terms of the GNU General Public License, version 2 or any
 later version published by the Free Software Foundation.

 This program is distributed in the hope that it will be useful, but
 WITHOUT ANY WARRANTY; without even the implied warranty of
 MERCHANTABILITY or FITNESS FOR A PARTICULAR PURPOSE. See the GNU General
 Public License for more details
-->
<robot name="moving_wall">
    <link name="basis">
        <inertial>
            <origin xyz="0 0 0" rpy="0 0 0" />
            <mass value="10"/>
            <inertia ixx="1"  ixy="0"  ixz="0" iyy="1" iyz="0" izz="1" />
        </inertial>
    </link>
    <link name="moving_wall">
        <inertial>
            <origin xyz="0 0 0" rpy="0 0 0" />
            <mass value="10"/>
            <inertia ixx="1"  ixy="0"  ixz="0" iyy="1" iyz="0" izz="1" />
        </inertial>
        <visual>
            <origin xyz="0 0 0" rpy="0 0 0" />
            <geometry>
                <box size="0.01 0.5 0.5"/>
            </geometry>
            <material name="material.metal">
                <color rgba=".8 0 0 1" />
            </material>
        </visual>
        <collision>
            <origin xyz="0 0 0" rpy="0 0 0" />
            <geometry>
                <box size="0.01 0.5 0.5"/>
            </geometry>
        </collision>
    </link>
    
    <joint name="prismatic_joint" type="prismatic">
        <origin xyz="0  0  0" rpy="0  0  0" />
        <parent link="basis"/>
        <child link="moving_wall" />
        <axis xyz="1  0  0" />
        <limit lower="-1" upper="1" effort="1000" velocity="10" />
    </joint>
</robot>

